Workbook

Sheet README
A1: CHATEAU IN THE WOODS | 4020 Monaco Drive, Indianapolis, IN 46220 | 118 Units
A2: Five-Year Cash Flow Model — Read Me, Deliverable Index & Material Assumptions
A3: Blue = hardcoded input / lever · Black = formula · Green = link to another sheet · Yellow fill = key assumption
A5: HOW THIS MODEL WORKS
A6: Single source of drivers | B6: Every economic assumption lives on the 'Assumptions' tab. All projection cells are formulas; changing a driver recalculates the model end-to-end, including the returns and both sensitivity grids.
A7: Model periodicity | B7: Annual (Year 1 – Year 5) operating model, driven by a 60-month renovation / downtime schedule on the 'Reno Schedule' tab. Month 1 = August 2026 (rent roll is dated 07/01/2026).
A8: Revenue engine | B8: Gross potential rent is built unit-by-unit from the 07/01/2026 rent roll: classic units carry in-place market rent, renovated units carry market rent plus the renovation premium, and units convert as the renovation schedule completes them.
A9: Data hierarchy | B9: Per the case instructions, the Excel rent roll and T-12 govern wherever they conflict with the Offering Memorandum. The OM is used only for facts the Excel files do not contain (unit W/D inventory, rent comps, tax analysis, physical condition, other-income policy detail).
A10: Capital funding convention | B10: All renovation and property capital is funded at closing through Sources & Uses (65% loan / 35% equity). Annual cash flow therefore deducts interest and replacement reserves only, and does not double-count capex. This is conservative — it puts the full equity out on day one with no timing benefit.
A12: TAB INDEX
A13: Assumptions | B13: All inputs and levers. Purchase price, growth, renovation scope, expenses, debt, exit.
A14: Rent Roll | B14: All 118 units from the 07/01/2026 rent roll, with case status rules and per-unit renovation scope applied.
A15: Unit Mix | B15: Floor-plan roll-up: in-place market rents, W/D inventory, renovation cost and premium, renovated rents.
A16: T-12 Recast | B16: T-12 (Feb-25 to Jan-26) actuals mapped to underwriting line items, with the Year-1 underwritten figure and variance.
A17: Other Income | B17: Line-by-line other-income build off T-12 actuals plus the identified ancillary upside, with implementation ramps.
A18: Capex Budget | B18: Non-unit capital: deferred maintenance, building systems and amenity scope, phased by year.
A19: Reno Schedule | B19: 60-month renovation schedule: units completed, capex spend, and renovation downtime vacancy.
A20: Annual Model | B20: The five-year cash flow: revenue build, operating expenses, NOI, capital and cash flow to equity.
A21: Returns | B21: Sources & Uses, debt, exit valuation, unlevered and levered IRR / equity multiple / cash-on-cash.
A22: Sensitivities | B22: Live grids: purchase price × exit cap (IRR and multiple) and renovation premium × exit cap.
A23: DD Questions | B23: Diligence request list, with the placeholder answer assumed in this model for each open item.
A25: MATERIAL ASSUMPTIONS — NOT PROVIDED IN THE CASE MATERIALS
A26: Item | B26: Assumption and basis
A27: Purchase price / basis | B27: $14,200,000 ($120,339/unit, $105.68/SF). The case does not state a price. Derived from the OM cover: a 6.9% Year-1 cap rate on CBRE's $980,838 Acquisition Forecast NOI implies $14.2mm, and 7.3% on the $1,034,543 Upgrade Forecast NOI implies $14.17mm. Treated as a lever — see the price sensitivity.
A28: Renovation scope and premium | B28: Comprehensive interior renovation of all 118 units: $13,000/unit for cabinets, counters, LVP flooring, appliances, lighting, plumbing fixtures, hardware and paint, at a $125/month premium. Plus $5,000/unit (per case instruction) to add hookups and a washer/dryer in the 65 units without one, at an incremental $75/month. Blended $15,754/unit at a $166/month premium = 12.7% return on cost.
A29: Renovated rent support | B29: Renovated rents of $1,250 (1x1) to $1,725 (3x2) sit inside the OM rent comp set. Avalon Lake (1974, same vintage, Graham Rd & Binford) achieves $1,178 / $1,655 / $1,834 for 1/2/3-bedrooms; submarket averages are $1,044 / $1,305 / $1,597. CBRE's own light-touch Upgrade Forecast is $1,094-$1,631 with a $50 premium and $1,375 on the Verdun with a W/D added.
A30: Renovation pace and downtime | B30: 5 units per month beginning month 3, completing all 118 units in month 26. Consistent with natural turnover (T-12 physical occupancy 93.2% implies roughly 55-60 turns a year). 14 days of incremental downtime per renovated unit over and above a normal turn.
A31: Market rent growth | B31: 3.0% per year. Above CBRE's 1.5%+1.5% two-step rollover assumption for 2026 and consistent with long-run Indianapolis Class B/C performance. Applied on a mid-year convention.
A32: Real estate taxes | B32: $140,000 in Year 1 (CBRE 2025-pay-2026 estimate with the SB-1 deduction is $135,374), stepping to $170,000 in Year 2 and $210,000 by Year 5. Indiana reassesses on sale; the OM's own comp study shows assessed value averaging 69% of sale price and rising 6.2% a year after a trade. THIS IS THE SINGLE LARGEST UNDERWRITING JUDGEMENT ON THE EXPENSE SIDE — see the DD Questions tab.
A33: Insurance | B33: $95,000 in Year 1 ($805/unit) growing 5%, versus $94,611 T-12 actual and CBRE's $88,326 forecast. No current loss run or bindable quote was provided.
A34: Bad debt | B34: 1.50% of GPR in Year 1 falling to 1.00% by Year 4. The T-12 shows $28,229 of gross bad debt against $19,050 of collections (net $9,179, 0.5%), but write-offs are accelerating (Jan-26 alone was $5,670) and the rent roll carries 4 units in eviction and 8 on notice.
A35: Exit | B35: 6.75% cap rate on forward (Year 6) NOI, 1.5% cost of sale, at the end of Year 5. Fifteen basis points inside the 6.90% going-in cap, reflecting a fully renovated asset with in-unit laundry throughout versus the classic condition being acquired.
A36: Debt | B36: 65% loan-to-cost on price plus all capital, 5.85% fixed, interest-only, 5-year term, 1% origination. Sized to a 10.4% Year-1 debt yield and a 1.38x Year-1 DSCR. No financing terms were provided.
A37: Excluded upside | B37: Not underwritten: converting the Building 4042 maintenance storage into two additional units, and converting 9 carports to garages. Both are real but return roughly 5-10% on cost, below the interior programme, and neither is needed for the recommendation.
A39: CONFLICTS BETWEEN SOURCES — AND HOW THEY WERE RESOLVED
A40: In-unit washer/dryer count | B40: The OM says '78 out of 118 units have a full size or stackable washer/dryer' but then lists only 53 side-by-side plus 1 stackable = 54, and its own floor-plan and building-mix schedules foot to 54 units with 'WD' in the unit code. The rent roll shows 53 units in a 'w/ WD' unit type (Rhone 15, Roman 4, Cabernet 4, Brunswick 30). Per the data hierarchy the rent roll governs: 53 units have laundry, 65 do not and carry the $5,000 addition. This is a confirmatory diligence item.
A41: Bordeaux washer/dryer unit | B41: The OM identifies one Bordeaux (4017-D) with a stackable washer/dryer at a $1,307 market rent. The rent roll shows all 25 Bordeaux units at a $1,260 market rent in a single 'Bordeaux' unit type. The rent roll governs, so 4017-D is underwritten as needing the $5,000 addition — conservative by $5,000.
A42: Market rents | B42: OM floor-plan mix (dated 09/08/2025) shows $1,044 / $1,109 / $1,174 / $1,343 / $1,212 / $1,257 / $1,581. The 07/01/2026 rent roll shows $1,050 / $1,125 / $1,165 / $1,350 / $1,250 / $1,260 / $1,600. The rent roll governs; it is also nine months newer.
A43: Occupancy | B43: The OM shows 105 occupied / 13 vacant as of 09/08/2025. The 07/01/2026 rent roll shows 114 occupied / 4 vacant (96.6%) after applying the case rules that 'Notice' and 'Evict' count as occupied. The rent roll governs.
A44: Trailing twelve months | B44: The OM's T-12 is August 2024 - July 2025 ($1,774,433 revenue / $799,669 NOI). The Excel T-12 provided is February 2025 - January 2026 ($1,790,101 revenue / $772,374 NOI on the property's own basis). The Excel T-12 governs and is recast on the 'T-12 Recast' tab.

Sheet Assumptions
A1: CHATEAU IN THE WOODS | 4020 Monaco Drive, Indianapolis, IN 46220 | 118 Units
A2: Underwriting Assumptions & Drivers
A3: Blue = hardcoded input / lever · Black = formula · Green = link to another sheet · Yellow fill = key assumption
A5: TRANSACTION
A6: Purchase Price | B6: 14200000 | H6: No price given in the case. Implied by the OM cover: 6.9% Yr-1 cap on CBRE's $980,838 Acquisition Forecast NOI. Primary lever — see Sensitivities.
A7: Price per Unit | B7: =Assumptions!$B$6/Assumptions!$B$17 -> 120338.98
A8: Price per Net Rentable SF | B8: =Assumptions!$B$6/Assumptions!$B$18 -> 105.67756
A9: Acquisition Costs (% of price) | B9: 0.015 | H9: Title, survey, legal, third-party reports, transfer costs.
A10: Analysis Start (Month 1) | B10: 2026-08-01 | H10: Rent roll is dated 07/01/2026; assumes an August 2026 close.
A11: Hold Period (years) | B11: 5
A12: Exit Cap Rate (on Year-6 NOI) | B12: 0.0675 | H12: 15 bps inside the going-in cap: a fully renovated asset with in-unit laundry throughout trades tighter than the classic product being acquired.
A13: Cost of Sale (% of gross value) | B13: 0.015
A14: Implied Going-In Cap (our Year-1 NOI) | B14: ='Annual Model'!C50/Assumptions!$B$6 -> 0.061720258 | H14: On our underwriting, not the broker's forecast. CBRE markets a 6.9% Year-1 cap rate on its own $980,838 Acquisition Forecast NOI, which is what implies the $14.2mm price above.
A16: PROPERTY — FROM RENT ROLL 07/01/2026
A17: Total Units | B17: 118 | H17: Rent roll total row.
A18: Net Rentable Square Feet | B18: 134371 | H18: Rent roll total row; ties to the OM.
A19: Average Unit Size (SF) | B19: =Assumptions!$B$18/Assumptions!$B$17 -> 1138.7373
A20: Year Built | B20: 1974 | H20: OM Property Summary.
A21: Occupied Units at Close | B21: 114 | H21: 102 Current + 8 Notice + 4 Evict. Case rules: 'Notice' and 'Evict' are treated as Occupied.
A22: Vacant Units at Close | B22: =Assumptions!$B$17-Assumptions!$B$21 -> 4 | H22: All four are 'Vacant-Unrented'.
A23: In-Place Physical Occupancy | B23: =Assumptions!$B$21/Assumptions!$B$17 -> 0.96610169
A24: In-Place Market Rent ($/month) | B24: ='Unit Mix'!$D$16 -> 153435
A25: In-Place Actual Rent ($/month) | B25: 144804.03 | H25: Rent roll total row. Occupied units only.
A26: In-Place Loss-to-Lease (occupied units) | B26: =1-Assumptions!$B$25/(Assumptions!$B$24-'Unit Mix'!$D$20) -> 0.022023908
A27: Units WITH In-Unit Washer/Dryer | B27: 53 | H27: Rent roll unit types containing 'w/ WD': Rhone 15, Roman 4, Cabernet 4, Brunswick 30.
A28: Units WITHOUT In-Unit Washer/Dryer | B28: =Assumptions!$B$17-Assumptions!$B$27 -> 65 | H28: Abbey 15, Verdun 25, Bordeaux 25. Each carries the $5,000 addition per the case instructions.
A30: RENOVATION PROGRAMME
A31: Renovation Start (month of hold) | B31: 3 | H31: Months 1-2 for permitting, GC mobilisation, mock-up units and leasing the 4 in-place vacants.
A32: Units Renovated per Month | B32: 5 | H32: 60/year against roughly 55-60 natural turns a year at 93% occupancy — renovations happen on the turn, not by forcing residents out. Completes all 118 units in month 26.
A33: Interior Renovation Cost / Unit | B33: 13000 | H33: Cabinets and counters, LVP flooring, black appliances, lighting and plumbing fixtures, hardware, full paint. Indianapolis classic-to-renovated scope on units last rehabbed in 2006.
A34: W/D Addition Cost / Unit (65 units) | B34: 5000 | H34: PRESCRIBED BY THE CASE: hookups plus the washer and dryer for every unit that does not have one.
A35: Blended Renovation Cost / Unit | B35: =(Assumptions!$B$27*Assumptions!$B$33+Assumptions!$B$28*(Assumptions!$B$33+Assumptions!$B$34))/Assumptions!$B$17 -> 15754.237
A36: Total Renovation Capital | B36: =Assumptions!$B$35*Assumptions!$B$17 -> 1859000
A37: Interior Renovation Premium ($/month) | B37: 125 | H37: All 118 units. Against CBRE's $50 light-touch premium; our scope is materially deeper.
A38: W/D Addition Premium ($/month) | B38: 75 | H38: Incremental, on the 65 units gaining laundry. CBRE forecasts $163 total on the Verdun for a light touch plus a W/D, versus our $200.
A39: Blended Premium / Unit ($/month) | B39: =(Assumptions!$B$27*Assumptions!$B$37+Assumptions!$B$28*(Assumptions!$B$37+Assumptions!$B$38))/Assumptions!$B$17 -> 166.31356
A40: Return on Renovation Cost | B40: =Assumptions!$B$39*12/Assumptions!$B$35 -> 0.12668101
A41: Incremental Downtime per Unit (days) | B41: 14 | H41: Over and above a normal turn. Renovation is executed inside the vacancy window.
A42: Capex Contingency (% of all capital) | B42: 0.08
A44: REVENUE DRIVERS
...

Sheet Rent Roll
A1: CHATEAU IN THE WOODS | 4020 Monaco Drive, Indianapolis, IN 46220 | 118 Units
A2: Rent Roll as of 07/01/2026 — with case status rules and per-unit renovation scope
A3: Blue = hardcoded input / lever · Black = formula · Green = link to another sheet · Yellow fill = key assumption
A5: Unit | B5: BD/BA | C5: Unit Type | D5: SF | E5: RR Status | F5: UW Status | G5: Market Rent | H5: In-Place Rent | I5: Loss to Lease | J5: Lease From | K5: Lease To | L5: In-Unit W/D | M5: Interior Reno $ | N5: W/D Add $ | O5: Total Reno $ | P5: Renovated Mkt Rent
A6: 4001-A | B6: 1/1.00 | C6: Rhone w/ WD | D6: 712 | E6: Current | F6: Occupied | G6: 1125 | H6: 1109 | I6: =IF(F6="Vacant",0,H6-G6) -> -16 | J6: 45590 | K6: 46319 | L6: Yes | M6: =Assumptions!$B$33 -> 13000 | N6: =IF(L6="No",Assumptions!$B$34,0) -> 0 | O6: =M6+N6 -> 13000 | P6: =G6+Assumptions!$B$37+IF(L6="No",Assumptions!$B$38,0) -> 1250
A7: 4001-C | B7: 1/1.00 | C7: Rhone w/ WD | D7: 712 | E7: Current | F7: Occupied | G7: 1125 | H7: 1094 | I7: =IF(F7="Vacant",0,H7-G7) -> -31 | J7: 44638 | K7: 46463 | L7: Yes | M7: =Assumptions!$B$33 -> 13000 | N7: =IF(L7="No",Assumptions!$B$34,0) -> 0 | O7: =M7+N7 -> 13000 | P7: =G7+Assumptions!$B$37+IF(L7="No",Assumptions!$B$38,0) -> 1250
A8: 4001-E | B8: 1/1.00 | C8: Rhone w/ WD | D8: 712 | E8: Current | F8: Occupied | G8: 1125 | H8: 1109 | I8: =IF(F8="Vacant",0,H8-G8) -> -16 | J8: 46173 | K8: 46568 | L8: Yes | M8: =Assumptions!$B$33 -> 13000 | N8: =IF(L8="No",Assumptions!$B$34,0) -> 0 | O8: =M8+N8 -> 13000 | P8: =G8+Assumptions!$B$37+IF(L8="No",Assumptions!$B$38,0) -> 1250
A9: 4002-B | B9: 1/1.00 | C9: Abbey | D9: 712 | E9: Current | F9: Occupied | G9: 1050 | H9: 1044 | I9: =IF(F9="Vacant",0,H9-G9) -> -6 | J9: 46142 | K9: 46536 | L9: No | M9: =Assumptions!$B$33 -> 13000 | N9: =IF(L9="No",Assumptions!$B$34,0) -> 5000 | O9: =M9+N9 -> 18000 | P9: =G9+Assumptions!$B$37+IF(L9="No",Assumptions!$B$38,0) -> 1250
A10: 4002-D | B10: 1/1.00 | C10: Abbey | D10: 712 | E10: Current | F10: Occupied | G10: 1050 | H10: 1063 | I10: =IF(F10="Vacant",0,H10-G10) -> 13 | J10: 45474 | K10: 46568 | L10: No | M10: =Assumptions!$B$33 -> 13000 | N10: =IF(L10="No",Assumptions!$B$34,0) -> 5000 | O10: =M10+N10 -> 18000 | P10: =G10+Assumptions!$B$37+IF(L10="No",Assumptions!$B$38,0) -> 1250
A11: 4002-F | B11: 1/1.00 | C11: Abbey | D11: 712 | E11: Current | F11: Occupied | G11: 1050 | H11: 1058 | I11: =IF(F11="Vacant",0,H11-G11) -> 8 | J11: 45108 | K11: 46568 | L11: No | M11: =Assumptions!$B$33 -> 13000 | N11: =IF(L11="No",Assumptions!$B$34,0) -> 5000 | O11: =M11+N11 -> 18000 | P11: =G11+Assumptions!$B$37+IF(L11="No",Assumptions!$B$38,0) -> 1250
A12: 4005-B | B12: 1/1.00 | C12: Abbey | D12: 712 | E12: Current | F12: Occupied | G12: 1050 | H12: 994 | I12: =IF(F12="Vacant",0,H12-G12) -> -56 | J12: 45990 | K12: 46384 | L12: No | M12: =Assumptions!$B$33 -> 13000 | N12: =IF(L12="No",Assumptions!$B$34,0) -> 5000 | O12: =M12+N12 -> 18000 | P12: =G12+Assumptions!$B$37+IF(L12="No",Assumptions!$B$38,0) -> 1250
A13: 4005-D | B13: 1/1.00 | C13: Abbey | D13: 712 | E13: Current | F13: Occupied | G13: 1050 | H13: 1044 | I13: =IF(F13="Vacant",0,H13-G13) -> -6 | J13: 45590 | L13: No | M13: =Assumptions!$B$33 -> 13000 | N13: =IF(L13="No",Assumptions!$B$34,0) -> 5000 | O13: =M13+N13 -> 18000 | P13: =G13+Assumptions!$B$37+IF(L13="No",Assumptions!$B$38,0) -> 1250
A14: 4005-F | B14: 1/1.00 | C14: Abbey | D14: 712 | E14: Current | F14: Occupied | G14: 1050 | H14: 1034 | I14: =IF(F14="Vacant",0,H14-G14) -> -16 | J14: 42644 | K14: 46295 | L14: No | M14: =Assumptions!$B$33 -> 13000 | N14: =IF(L14="No",Assumptions!$B$34,0) -> 5000 | O14: =M14+N14 -> 18000 | P14: =G14+Assumptions!$B$37+IF(L14="No",Assumptions!$B$38,0) -> 1250
A15: 4006-A | B15: 1/1.00 | C15: Rhone w/ WD | D15: 712 | E15: Current | F15: Occupied | G15: 1125 | H15: 1109 | I15: =IF(F15="Vacant",0,H15-G15) -> -16 | J15: 44263 | K15: 46363 | L15: Yes | M15: =Assumptions!$B$33 -> 13000 | N15: =IF(L15="No",Assumptions!$B$34,0) -> 0 | O15: =M15+N15 -> 13000 | P15: =G15+Assumptions!$B$37+IF(L15="No",Assumptions!$B$38,0) -> 1250
A16: 4006-C | B16: 1/1.00 | C16: Rhone w/ WD | D16: 712 | E16: Current | F16: Occupied | G16: 1125 | H16: 1094 | I16: =IF(F16="Vacant",0,H16-G16) -> -31 | J16: 43896 | K16: 46451 | L16: Yes | M16: =Assumptions!$B$33 -> 13000 | N16: =IF(L16="No",Assumptions!$B$34,0) -> 0 | O16: =M16+N16 -> 13000 | P16: =G16+Assumptions!$B$37+IF(L16="No",Assumptions!$B$38,0) -> 1250
A17: 4006-E | B17: 1/1.00 | C17: Rhone w/ WD | D17: 712 | E17: Current | F17: Occupied | G17: 1125 | H17: 1099 | I17: =IF(F17="Vacant",0,H17-G17) -> -26 | J17: 45717 | K17: 46356 | L17: Yes | M17: =Assumptions!$B$33 -> 13000 | N17: =IF(L17="No",Assumptions!$B$34,0) -> 0 | O17: =M17+N17 -> 13000 | P17: =G17+Assumptions!$B$37+IF(L17="No",Assumptions!$B$38,0) -> 1250
A18: 4025-C | B18: 1/1.00 | C18: Rhone w/ WD | D18: 712 | E18: Current | F18: Occupied | G18: 1125 | H18: 999 | I18: =IF(F18="Vacant",0,H18-G18) -> -126 | J18: 45991 | K18: 46385 | L18: Yes | M18: =Assumptions!$B$33 -> 13000 | N18: =IF(L18="No",Assumptions!$B$34,0) -> 0 | O18: =M18+N18 -> 13000 | P18: =G18+Assumptions!$B$37+IF(L18="No",Assumptions!$B$38,0) -> 1250
A19: 4025-E | B19: 1/1.00 | C19: Rhone w/ WD | D19: 712 | E19: Current | F19: Occupied | G19: 1125 | H19: 1079 | I19: =IF(F19="Vacant",0,H19-G19) -> -46 | J19: 45518 | K19: 46247 | L19: Yes | M19: =Assumptions!$B$33 -> 13000 | N19: =IF(L19="No",Assumptions!$B$34,0) -> 0 | O19: =M19+N19 -> 13000 | P19: =G19+Assumptions!$B$37+IF(L19="No",Assumptions!$B$38,0) -> 1250
A20: 4029-B | B20: 1/1.00 | C20: Abbey | D20: 712 | E20: Current | F20: Occupied | G20: 1050 | H20: 1044 | I20: =IF(F20="Vacant",0,H20-G20) -> -6 | J20: 46172 | K20: 46567 | L20: No | M20: =Assumptions!$B$33 -> 13000 | N20: =IF(L20="No",Assumptions!$B$34,0) -> 5000 | O20: =M20+N20 -> 18000 | P20: =G20+Assumptions!$B$37+IF(L20="No",Assumptions!$B$38,0) -> 1250
A21: 4029-D | B21: 1/1.00 | C21: Abbey | D21: 712 | E21: Current | F21: Occupied | G21: 1050 | H21: 1044 | I21: =IF(F21="Vacant",0,H21-G21) -> -6 | J21: 45912 | K21: 46306 | L21: No | M21: =Assumptions!$B$33 -> 13000 | N21: =IF(L21="No",Assumptions!$B$34,0) -> 5000 | O21: =M21+N21 -> 18000 | P21: =G21+Assumptions!$B$37+IF(L21="No",Assumptions!$B$38,0) -> 1250
A22: 4029-F | B22: 1/1.00 | C22: Abbey | D22: 712 | E22: Current | F22: Occupied | G22: 1050 | H22: 1044 | I22: =IF(F22="Vacant",0,H22-G22) -> -6 | J22: 43847 | L22: No | M22: =Assumptions!$B$33 -> 13000 | N22: =IF(L22="No",Assumptions!$B$34,0) -> 5000 | O22: =M22+N22 -> 18000 | P22: =G22+Assumptions!$B$37+IF(L22="No",Assumptions!$B$38,0) -> 1250
A23: 4033-A | B23: 1/1.00 | C23: Rhone w/ WD | D23: 712 | E23: Current | F23: Occupied | G23: 1125 | H23: 1084 | I23: =IF(F23="Vacant",0,H23-G23) -> -41 | J23: 45531 | K23: 46260 | L23: Yes | M23: =Assumptions!$B$33 -> 13000 | N23: =IF(L23="No",Assumptions!$B$34,0) -> 0 | O23: =M23+N23 -> 13000 | P23: =G23+Assumptions!$B$37+IF(L23="No",Assumptions!$B$38,0) -> 1250
A24: 4033-C | B24: 1/1.00 | C24: Rhone w/ WD | D24: 712 | E24: Current | F24: Occupied | G24: 1125 | H24: 1109 | I24: =IF(F24="Vacant",0,H24-G24) -> -16 | J24: 46130 | K24: 46524 | L24: Yes | M24: =Assumptions!$B$33 -> 13000 | N24: =IF(L24="No",Assumptions!$B$34,0) -> 0 | O24: =M24+N24 -> 13000 | P24: =G24+Assumptions!$B$37+IF(L24="No",Assumptions!$B$38,0) -> 1250
A25: 4033-E | B25: 1/1.00 | C25: Rhone w/ WD | D25: 712 | E25: Current | F25: Occupied | G25: 1125 | H25: 1109 | I25: =IF(F25="Vacant",0,H25-G25) -> -16 | J25: 40207 | K25: 46418 | L25: Yes | M25: =Assumptions!$B$33 -> 13000 | N25: =IF(L25="No",Assumptions!$B$34,0) -> 0 | O25: =M25+N25 -> 13000 | P25: =G25+Assumptions!$B$37+IF(L25="No",Assumptions!$B$38,0) -> 1250
A26: 4034-B | B26: 1/1.00 | C26: Abbey | D26: 712 | E26: Current | F26: Occupied | G26: 1050 | H26: 1029 | I26: =IF(F26="Vacant",0,H26-G26) -> -21 | J26: 44680 | K26: 46505 | L26: No | M26: =Assumptions!$B$33 -> 13000 | N26: =IF(L26="No",Assumptions!$B$34,0) -> 5000 | O26: =M26+N26 -> 18000 | P26: =G26+Assumptions!$B$37+IF(L26="No",Assumptions!$B$38,0) -> 1250
A27: 4034-D | B27: 1/1.00 | C27: Abbey | D27: 712 | E27: Current | F27: Occupied | G27: 1050 | H27: 1044 | I27: =IF(F27="Vacant",0,H27-G27) -> -6 | J27: 45961 | K27: 46356 | L27: No | M27: =Assumptions!$B$33 -> 13000 | N27: =IF(L27="No",Assumptions!$B$34,0) -> 5000 | O27: =M27+N27 -> 18000 | P27: =G27+Assumptions!$B$37+IF(L27="No",Assumptions!$B$38,0) -> 1250
A28: 4034-F | B28: 1/1.00 | C28: Abbey | D28: 712 | E28: Current | F28: Occupied | G28: 1050 | H28: 1044 | I28: =IF(F28="Vacant",0,H28-G28) -> -6 | J28: 46105 | K28: 46500 | L28: No | M28: =Assumptions!$B$33 -> 13000 | N28: =IF(L28="No",Assumptions!$B$34,0) -> 5000 | O28: =M28+N28 -> 18000 | P28: =G28+Assumptions!$B$37+IF(L28="No",Assumptions!$B$38,0) -> 1250
A29: 4037-D | B29: 1/1.00 | C29: Abbey | D29: 712 | E29: Current | F29: Occupied | G29: 1050 | H29: 1044 | I29: =IF(F29="Vacant",0,H29-G29) -> -6 | J29: 46101 | K29: 46496 | L29: No | M29: =Assumptions!$B$33 -> 13000 | N29: =IF(L29="No",Assumptions!$B$34,0) -> 5000 | O29: =M29+N29 -> 18000 | P29: =G29+Assumptions!$B$37+IF(L29="No",Assumptions!$B$38,0) -> 1250
A30: 4037-F | B30: 1/1.00 | C30: Abbey | D30: 712 | E30: Current | F30: Occupied | G30: 1050 | H30: 1044 | I30: =IF(F30="Vacant",0,H30-G30) -> -6 | J30: 45566 | K30: 46295 | L30: No | M30: =Assumptions!$B$33 -> 13000 | N30: =IF(L30="No",Assumptions!$B$34,0) -> 5000 | O30: =M30+N30 -> 18000 | P30: =G30+Assumptions!$B$37+IF(L30="No",Assumptions!$B$38,0) -> 1250
A31: 4038-A | B31: 1/1.00 | C31: Rhone w/ WD | D31: 712 | E31: Current | F31: Occupied | G31: 1125 | H31: 1094 | I31: =IF(F31="Vacant",0,H31-G31) -> -31 | J31: 45710 | K31: 46439 | L31: Yes | M31: =Assumptions!$B$33 -> 13000 | N31: =IF(L31="No",Assumptions!$B$34,0) -> 0 | O31: =M31+N31 -> 13000 | P31: =G31+Assumptions!$B$37+IF(L31="No",Assumptions!$B$38,0) -> 1250
A32: 4038-E | B32: 1/1.00 | C32: Rhone w/ WD | D32: 712 | E32: Current | F32: Occupied | G32: 1125 | H32: 1109 | I32: =IF(F32="Vacant",0,H32-G32) -> -16 | J32: 45919 | K32: 46313 | L32: Yes | M32: =Assumptions!$B$33 -> 13000 | N32: =IF(L32="No",Assumptions!$B$34,0) -> 0 | O32: =M32+N32 -> 13000 | P32: =G32+Assumptions!$B$37+IF(L32="No",Assumptions!$B$38,0) -> 1250
A33: 4038-C | B33: 1/1.00 | C33: Rhone w/ WD | D33: 712 | E33: Evict | F33: Occupied | G33: 1125 | H33: 1109 | I33: =IF(F33="Vacant",0,H33-G33) -> -16 | J33: 46066 | K33: 46458 | L33: Yes | M33: =Assumptions!$B$33 -> 13000 | N33: =IF(L33="No",Assumptions!$B$34,0) -> 0 | O33: =M33+N33 -> 13000 | P33: =G33+Assumptions!$B$37+IF(L33="No",Assumptions!$B$38,0) -> 1250
A34: 4025-A | B34: 1/1.00 | C34: Rhone w/ WD | D34: 712 | E34: Notice-Unrented | F34: Occupied | G34: 1125 | H34: 1079 | I34: =IF(F34="Vacant",0,H34-G34) -> -46 | J34: 45506 | K34: 46235 | L34: Yes | M34: =Assumptions!$B$33 -> 13000 | N34: =IF(L34="No",Assumptions!$B$34,0) -> 0 | O34: =M34+N34 -> 13000 | P34: =G34+Assumptions!$B$37+IF(L34="No",Assumptions!$B$38,0) -> 1250
... A40: 4010-A | B40: 2/1.00 | C40: Cabernet w/ WD | D40: 1182 | E40: Current | F40: Occupied | G40: 1350 | H40: 1329 | I40: =IF(F40="Vacant",0,H40-G40) -> -21 | J40: 44708 | K40: 46533 | L40: Yes | M40: =Assumptions!$B$33 -> 13000 | N40: =IF(L40="No",Assumptions!$B$34,0) -> 0 | O40: =M40+N40 -> 13000 | P40: =G40+Assumptions!$B$37+IF(L40="No",Assumptions!$B$38,0) -> 1475
A41: 4013-A | B41: 2/1.00 | C41: Cabernet w/ WD | D41: 1182 | E41: Current | F41: Occupied | G41: 1350 | H41: 1343 | I41: =IF(F41="Vacant",0,H41-G41) -> -7 | J41: 45077 | L41: Yes | M41: =Assumptions!$B$33 -> 13000 | N41: =IF(L41="No",Assumptions!$B$34,0) -> 0 | O41: =M41+N41 -> 13000 | P41: =G41+Assumptions!$B$37+IF(L41="No",Assumptions!$B$38,0) -> 1475
A42: 4021-A | B42: 2/1.00 | C42: Cabernet w/ WD | D42: 1182 | E42: Current | F42: Occupied | G42: 1350 | H42: 1337 | I42: =IF(F42="Vacant",0,H42-G42) -> -13 | J42: 44459 | K42: 46284 | L42: Yes | M42: =Assumptions!$B$33 -> 13000 | N42: =IF(L42="No",Assumptions!$B$34,0) -> 0 | O42: =M42+N42 -> 13000 | P42: =G42+Assumptions!$B$37+IF(L42="No",Assumptions!$B$38,0) -> 1475
A43: 4045-A | B43: 2/1.00 | C43: Cabernet w/ WD | D43: 1182 | E43: Current | F43: Occupied | G43: 1350 | H43: 1343 | I43: =IF(F43="Vacant",0,H43-G43) -> -7 | J43: 46112 | K43: 46506 | L43: Yes | M43: =Assumptions!$B$33 -> 13000 | N43: =IF(L43="No",Assumptions!$B$34,0) -> 0 | O43: =M43+N43 -> 13000 | P43: =G43+Assumptions!$B$37+IF(L43="No",Assumptions!$B$38,0) -> 1475
A44: 4009-A | B44: 2/2.00 | C44: Verdun | D44: 1105 | E44: Current | F44: Occupied | G44: 1250 | H44: 1212 | I44: =IF(F44="Vacant",0,H44-G44) -> -38 | J44: 44862 | K44: 46322 | L44: No | M44: =Assumptions!$B$33 -> 13000 | N44: =IF(L44="No",Assumptions!$B$34,0) -> 5000 | O44: =M44+N44 -> 18000 | P44: =G44+Assumptions!$B$37+IF(L44="No",Assumptions!$B$38,0) -> 1450
A45: 4009-B | B45: 2/2.00 | C45: Bordeaux | D45: 1182 | E45: Current | F45: Occupied | G45: 1260 | H45: 1249 | I45: =IF(F45="Vacant",0,H45-G45) -> -11 | J45: 45233 | K45: 46328 | L45: No | M45: =Assumptions!$B$33 -> 13000 | N45: =IF(L45="No",Assumptions!$B$34,0) -> 5000 | O45: =M45+N45 -> 18000 | P45: =G45+Assumptions!$B$37+IF(L45="No",Assumptions!$B$38,0) -> 1460
A46: 4009-C | B46: 2/2.00 | C46: Verdun | D46: 1105 | E46: Current | F46: Occupied | G46: 1250 | H46: 1206 | I46: =IF(F46="Vacant",0,H46-G46) -> -44 | J46: 45768 | K46: 46497 | L46: No | M46: =Assumptions!$B$33 -> 13000 | N46: =IF(L46="No",Assumptions!$B$34,0) -> 5000 | O46: =M46+N46 -> 18000 | P46: =G46+Assumptions!$B$37+IF(L46="No",Assumptions!$B$38,0) -> 1450
...

Sheet Unit Mix
A1: CHATEAU IN THE WOODS | 4020 Monaco Drive, Indianapolis, IN 46220 | 118 Units
A2: Floor Plan Mix, Renovation Scope and Renovated Rents (rent roll 07/01/2026)
A3: Blue = hardcoded input / lever · Black = formula · Green = link to another sheet · Yellow fill = key assumption
A5: Floor Plan | B5: Type | C5: Units | D5: % of Total | E5: SF / Unit | F5: Total SF | G5: In-Unit W/D | H5: Occ. Units | I5: Market Rent | J5: Market Rent PSF | K5: In-Place Rent (occ) | L5: Avg In-Place Rent | M5: Loss to Lease | N5: Reno Cost / Unit | O5: Reno Prem. / Month | P5: Renovated Mkt Rent | Q5: Renov. Rent PSF
A6: Abbey | B6: 1/1 | C6: 15 | D6: =C6/$C$13 -> 0.12711864 | E6: 712 | F6: =C6*E6 -> 10680 | G6: No | H6: 15 | I6: 1050 | J6: =I6/E6 -> 1.4747191 | K6: 15618 | L6: =IF(H6=0,0,K6/H6) -> 1041.2 | M6: =IF(H6=0,0,L6/I6-1) -> -0.0083809524 | N6: =Assumptions!$B$33+IF(G6="No",Assumptions!$B$34,0) -> 18000 | O6: =Assumptions!$B$37+IF(G6="No",Assumptions!$B$38,0) -> 200 | P6: =I6+O6 -> 1250 | Q6: =P6/E6 -> 1.755618
A7: Rhone w/ WD | B7: 1/1 | C7: 15 | D7: =C7/$C$13 -> 0.12711864 | E7: 712 | F7: =C7*E7 -> 10680 | G7: Yes | H7: 15 | I7: 1125 | J7: =I7/E7 -> 1.5800562 | K7: 16385 | L7: =IF(H7=0,0,K7/H7) -> 1092.3333 | M7: =IF(H7=0,0,L7/I7-1) -> -0.029037037 | N7: =Assumptions!$B$33+IF(G7="No",Assumptions!$B$34,0) -> 13000 | O7: =Assumptions!$B$37+IF(G7="No",Assumptions!$B$38,0) -> 125 | P7: =I7+O7 -> 1250 | Q7: =P7/E7 -> 1.755618
A8: Roman w/ WD | B8: 1/1.5 | C8: 4 | D8: =C8/$C$13 -> 0.033898305 | E8: 852 | F8: =C8*E8 -> 3408 | G8: Yes | H8: 4 | I8: 1165 | J8: =I8/E8 -> 1.3673709 | K8: 4656 | L8: =IF(H8=0,0,K8/H8) -> 1164 | M8: =IF(H8=0,0,L8/I8-1) -> -0.0008583691 | N8: =Assumptions!$B$33+IF(G8="No",Assumptions!$B$34,0) -> 13000 | O8: =Assumptions!$B$37+IF(G8="No",Assumptions!$B$38,0) -> 125 | P8: =I8+O8 -> 1290 | Q8: =P8/E8 -> 1.5140845
A9: Cabernet w/ WD | B9: 2/1 | C9: 4 | D9: =C9/$C$13 -> 0.033898305 | E9: 1182 | F9: =C9*E9 -> 4728 | G9: Yes | H9: 4 | I9: 1350 | J9: =I9/E9 -> 1.142132 | K9: 5352 | L9: =IF(H9=0,0,K9/H9) -> 1338 | M9: =IF(H9=0,0,L9/I9-1) -> -0.0088888889 | N9: =Assumptions!$B$33+IF(G9="No",Assumptions!$B$34,0) -> 13000 | O9: =Assumptions!$B$37+IF(G9="No",Assumptions!$B$38,0) -> 125 | P9: =I9+O9 -> 1475 | Q9: =P9/E9 -> 1.2478849
A10: Verdun | B10: 2/2 | C10: 25 | D10: =C10/$C$13 -> 0.21186441 | E10: 1105 | F10: =C10*E10 -> 27625 | G10: No | H10: 24 | I10: 1250 | J10: =I10/E10 -> 1.1312217 | K10: 28580.03 | L10: =IF(H10=0,0,K10/H10) -> 1190.8346 | M10: =IF(H10=0,0,L10/I10-1) -> -0.047332333 | N10: =Assumptions!$B$33+IF(G10="No",Assumptions!$B$34,0) -> 18000 | O10: =Assumptions!$B$37+IF(G10="No",Assumptions!$B$38,0) -> 200 | P10: =I10+O10 -> 1450 | Q10: =P10/E10 -> 1.3122172
A11: Bordeaux | B11: 2/2 | C11: 25 | D11: =C11/$C$13 -> 0.21186441 | E11: 1182 | F11: =C11*E11 -> 29550 | G11: No | H11: 23 | I11: 1260 | J11: =I11/E11 -> 1.0659898 | K11: 28802 | L11: =IF(H11=0,0,K11/H11) -> 1252.2609 | M11: =IF(H11=0,0,L11/I11-1) -> -0.006142167 | N11: =Assumptions!$B$33+IF(G11="No",Assumptions!$B$34,0) -> 18000 | O11: =Assumptions!$B$37+IF(G11="No",Assumptions!$B$38,0) -> 200 | P11: =I11+O11 -> 1460 | Q11: =P11/E11 -> 1.2351946
A12: Brunswick w/ WD | B12: 3/2 | C12: 30 | D12: =C12/$C$13 -> 0.25423729 | E12: 1590 | F12: =C12*E12 -> 47700 | G12: Yes | H12: 29 | I12: 1600 | J12: =I12/E12 -> 1.0062893 | K12: 45411 | L12: =IF(H12=0,0,K12/H12) -> 1565.8966 | M12: =IF(H12=0,0,L12/I12-1) -> -0.021314655 | N12: =Assumptions!$B$33+IF(G12="No",Assumptions!$B$34,0) -> 13000 | O12: =Assumptions!$B$37+IF(G12="No",Assumptions!$B$38,0) -> 125 | P12: =I12+O12 -> 1725 | Q12: =P12/E12 -> 1.0849057
A13: Total / Weighted Average | C13: =SUM(C6:C12) -> 118 | D13: =SUM(D6:D12) -> 1 | E13: =F13/C13 -> 1138.7373 | F13: =SUM(F6:F12) -> 134371 | G13: =SUMIF(G6:G12,"Yes",C6:C12)&" of "&C13 -> 53 of 118 | H13: =SUM(H6:H12) -> 114 | I13: =SUMPRODUCT(C6:C12,I6:I12)/C13 -> 1300.2966 | J13: =SUMPRODUCT(C6:C12,I6:I12)/F13 -> 1.1418759 | K13: =SUM(K6:K12) -> 144804.03 | L13: =K13/H13 -> 1270.2108 | M13: =L13/(SUMPRODUCT(H6:H12,I6:I12)/H13)-1 -> -0.022023908 | N13: =SUMPRODUCT(C6:C12,N6:N12)/C13 -> 15754.237 | O13: =SUMPRODUCT(C6:C12,O6:O12)/C13 -> 166.31356 | P13: =SUMPRODUCT(C6:C12,P6:P12)/C13 -> 1466.6102 | Q13: =SUMPRODUCT(C6:C12,P6:P12)/F13 -> 1.2879267
A15: AGGREGATE RENT POTENTIAL
A16: Total Market Rent — Classic Condition ($/month) | D16: =SUMPRODUCT(C6:C12,I6:I12) -> 153435
A17: Total Market Rent — Renovated ($/month) | D17: =SUMPRODUCT(C6:C12,P6:P12) -> 173060
A18: Average Market Rent / Unit — Classic | D18: =D16/C13 -> 1300.2966
A19: Average Market Rent / Unit — Renovated | D19: =D17/C13 -> 1466.6102
A20: Market Rent of the 4 Vacant Units ($/month) | D20: =SUMPRODUCT((C6:C12-H6:H12),I6:I12) -> 5370
A21: Total Renovation Capital ($) | D21: =SUMPRODUCT(C6:C12,N6:N12) -> 1859000
A22: Units Requiring W/D Addition | D22: =SUMIF(G6:G12,"No",C6:C12) -> 65
A24: Unit counts, square footage, market rents and in-place rents are taken directly from the 07/01/2026 rent roll and foot to its total row ($153,435 market / $144,804 in-place / 134,371 SF). Renovation cost and premium are driven from the Assumptions tab.

Sheet T-12 Recast
A1: CHATEAU IN THE WOODS | 4020 Monaco Drive, Indianapolis, IN 46220 | 118 Units
A2: T-12 Actuals (Feb 2025 – Jan 2026) Recast to Underwriting Line Items
A3: Blue = hardcoded input / lever · Black = formula · Green = link to another sheet · Yellow fill = key assumption
A5: REVENUE
B6: T-12 Actual | C6: Per Unit | D6: UW Year 1 | E6: Variance | F6: Underwriting note
A7: Gross Rent Potential | B7: 1813657 | C7: =B7/Assumptions!$B$17 -> 15369.975 | D7: ='Annual Model'!C21 -> 1906611.9 | E7: =IF(B7=0,"n/a",D7/B7-1) -> 0.051252758 | F7: T-12 gross rent potential at then-current market rents. UW Year 1 reflects the 07/01/2026 rent roll, renovated-unit premiums as they come online, and market rent growth.
A8: Economic Vacancy / Loss to Lease | B8: -31322.94 | C8: =B8/Assumptions!$B$17 -> -265.44864 | D8: ='Annual Model'!C23 -> -41945.462 | E8: =IF(B8=0,"n/a",D8/B8-1) -> 0.33912916 | F8: T-12 loss to lease is 1.7% of GPR. Rent roll shows 2.2% in place today.
A9: Physical Vacancy | B9: -171096 | C9: =B9/Assumptions!$B$17 -> -1449.9661 | D9: ='Annual Model'!C24+'Annual Model'!C25 -> -126748.4 | E9: =IF(B9=0,"n/a",D9/B9-1) -> -0.25919717 | F9: T-12 physical vacancy is 9.4% of GPR (and deteriorating: Jan-26 alone was $20,757). UW is 5.0% operating plus renovation downtime.
A10: Concessions | B10: -9688 | C10: =B10/Assumptions!$B$17 -> -82.101695 | D10: ='Annual Model'!C26 -> -14299.589 | E10: =IF(B10=0,"n/a",D10/B10-1) -> 0.47601047 | F10: T-12 $9,688. Concessions restarted in Aug-25 after a year at zero.
A11: Bad Debt, net of collections | B11: -9179.26 | C11: =B11/Assumptions!$B$17 -> -77.790339 | D11: ='Annual Model'!C27 -> -28599.179 | E11: =IF(B11=0,"n/a",D11/B11-1) -> 2.1156301 | F11: T-12 gross write-offs $28,229 less $19,050 collected = $9,179 net (0.5%). Underwritten at 1.5% falling to 1.0% given 4 evictions and 8 notices on the rent roll.
A12: Net Rental Income | B12: 1592370.8 | C12: =B12/Assumptions!$B$17 -> 13494.668 | D12: ='Annual Model'!C28 -> 1695019.3 | E12: =IF(B12=0,"n/a",D12/B12-1) -> 0.064462682
A14: OTHER INCOME
A15: Carport / Garage Rent (74 carports @ $25) | B15: 16197 | C15: =B15/Assumptions!$B$17 -> 137.26271
A16: Storage Rent (5 of 23 rented @ $15-20) | B16: 141 | C16: =B16/Assumptions!$B$17 -> 1.1949153
A17: Credit Builder Fees | B17: 2346.11 | C17: =B17/Assumptions!$B$17 -> 19.882288
A18: Onsite Transfer Fees | B18: 200 | C18: =B18/Assumptions!$B$17 -> 1.6949153
A19: Administrative Fees | B19: 5250 | C19: =B19/Assumptions!$B$17 -> 44.491525
A20: Utility Fees (water/sewer + valet trash bundled) | B20: 97811.57 | C20: =B20/Assumptions!$B$17 -> 828.91161
A21: Technology Fee ($49 bulk internet, ramping) | B21: 13553 | C21: =B21/Assumptions!$B$17 -> 114.85593
A22: Lease Termination Fees | B22: 4000 | C22: =B22/Assumptions!$B$17 -> 33.898305
A23: Eviction Fees | B23: 3095.96 | C23: =B23/Assumptions!$B$17 -> 26.236949
A24: Washer/Dryer Rental (programme discontinued) | B24: 209 | C24: =B24/Assumptions!$B$17 -> 1.7711864
A25: Application Fees | B25: 7050 | C25: =B25/Assumptions!$B$17 -> 59.745763
A26: Utility Reimbursement | B26: 545.93 | C26: =B26/Assumptions!$B$17 -> 4.6265254
... A32: Damage Charges (cleaning, flooring, paint, other) | B32: 20467.4 | C32: =B32/Assumptions!$B$17 -> 173.45254
A33: Total Operating Other Income | B33: =SUM(B15:B32) -> 193597.53 | C33: =B33/Assumptions!$B$17 -> 1640.657 | D33: ='Other Income'!C25 -> 238318.9 | E33: =IF(B33=0,"n/a",D33/B33-1) -> 0.23100176 | F33: Interest income of $4,133 is excluded as non-property income. Bad debt is shown above as a revenue deduction rather than netted in other income.
A34: Memo: Interest Income (excluded) | B34: 4132.89 | C34: =B34/Assumptions!$B$17 -> 35.024492 | F34: Excluded from underwritten revenue — a function of the seller's cash balances, not the real estate.
A36: OPERATING EXPENSES
B37: T-12 Actual | C37: Per Unit | D37: UW Year 1 | E37: Variance | F37: Underwriting note
A38: Payroll (incl. contract labour) | B38: 227969.28 | C38: =B38/Assumptions!$B$17 -> 1931.9431 | D38: =Assumptions!$B$55 -> 235000 | E38: =D38/B38-1 -> 0.030840647 | F38: T-12 $227,969 ($1,932/unit) including $9,778 of contract labour. CBRE forecast $229,021 for a manager, part-time leasing, maintenance supervisor and one technician. We fund a second technician.
A39: Property Management Fee | B39: 62064.01 | C39: =B39/Assumptions!$B$17 -> 525.96619 | D39: ='Annual Model'!C36 -> 77333.528 | E39: =D39/B39-1 -> 0.24602854 | F39: T-12 is an effective 3.5% of revenue. Underwritten at a market 4.0% of effective gross revenue.
A40: Marketing & Advertising | B40: 26399.14 | C40: =B40/Assumptions!$B$17 -> 223.72153 | D40: =Assumptions!$B$57 -> 28000 | E40: =D40/B40-1 -> 0.060640612 | F40: T-12 $26,399, of which $22,047 is ILS. Increased modestly for renovated-unit lease-up.
A41: General & Administrative | B41: 62885.88 | C41: =B41/Assumptions!$B$17 -> 532.93119 | D41: =Assumptions!$B$58 -> 50000 | E41: =D41/B41-1 -> -0.20490896 | F41: T-12 $62,887 includes $17,528 legal and $14,730 tax/audit concentrated in Dec-25/Jan-26, almost certainly transaction-related. CBRE forecast $42,209. Underwritten at $50,000 between the two.
A42: Bulk Internet | B42: 11068.2 | C42: =B42/Assumptions!$B$17 -> 93.798305 | D42: =Assumptions!$B$59 -> 39577 | E42: =D42/B42-1 -> 2.5757395 | F42: T-12 $11,068 captures only 7 months of a ramping contract. Stabilised is $27.95/unit/month = $39,577. Understating this line is the easiest way to overstate NOI on this deal.
A43: Electricity (common + vacant) | B43: 30319.93 | C43: =B43/Assumptions!$B$17 -> 256.94856 | D43: =Assumptions!$B$60 -> 31000 | E43: =D43/B43-1 -> 0.022429801 | F43: T-12 $30,320 across corporate and vacant-unit meters.
A44: Gas (central hot water + common) | B44: 15330.1 | C44: =B44/Assumptions!$B$17 -> 129.9161 | D44: =Assumptions!$B$61 -> 16000 | E44: =D44/B44-1 -> 0.043698345 | F44: T-12 $15,330. Central gas water heaters plus 8 individual electric.
A45: Water & Sewer | B45: 86468.36 | C45: =B45/Assumptions!$B$17 -> 732.78271 | D45: =Assumptions!$B$62 -> 90000 | E45: =D45/B45-1 -> 0.040843148 | F45: T-12 $86,468. Master-metered and billed back to residents; recovery is modelled at 85% in Other Income.
A46: Repairs & Maintenance (incl. turns) | B46: 250934.72 | C46: =B46/Assumptions!$B$17 -> 2126.5654 | D46: =Assumptions!$B$63 -> 255000 | E46: =D46/B46-1 -> 0.016200548 | F46: T-12 $250,935 ($2,127/unit) including $42,921 of turnover cost. No post-renovation savings credited, though a fully renovated portfolio should run lighter.
A47: Insurance | B47: 94611.24 | C47: =B47/Assumptions!$B$17 -> 801.79017 | D47: =Assumptions!$B$64 -> 95000 | E47: =D47/B47-1 -> 0.0041090255 | F47: T-12 $94,611 ($802/unit). CBRE forecast $88,326. Held at T-12 plus a small cushion pending a loss run.
A48: Real Estate Taxes | B48: 149676.52 | C48: =B48/Assumptions!$B$17 -> 1268.4451 | D48: ='Annual Model'!C45 -> 140000 | E48: =D48/B48-1 -> -0.064649552 | F48: T-12 $149,677 including a $17,958 October catch-up. CBRE's 2025-pay-2026 estimate with the SB-1 deduction is $135,374. Year 1 $140,000 stepping to $210,000 by Year 5 for reassessment on sale.
...

Sheet Other Income
A1: CHATEAU IN THE WOODS | 4020 Monaco Drive, Indianapolis, IN 46220 | 118 Units
A2: Other Income Build — T-12 Actuals plus Identified Ancillary Upside
A3: Blue = hardcoded input / lever · Black = formula · Green = link to another sheet · Yellow fill = key assumption
B5: T-12 Actual | C5: Year 1 | D5: Year 2 | E5: Year 3 | F5: Year 4 | G5: Year 5 | H5: Basis
A6: Ramp — Technology Fee ($49) implementation | C6: 0.85 | D6: 1 | E6: 1 | F6: 1 | G6: 1 | H6: Contract signed May 2025 and implemented on new leases and renewals over 13 months. Jan-26 booked $3,303 of a $5,489 full month, i.e. 60% penetrated at the T-12 close.
A7: Ramp — Valet Trash ($25) implementation | C7: 0.75 | D7: 0.95 | E7: 1 | F7: 1 | G7: 1 | H7: Charged on new leases and renewals. The property begins paying the valet contractor in Jan-2026.
A8: Ramp — Pet Rent (new policy) | C8: 0.5 | D8: 1 | E8: 1 | F8: 1 | G8: 1 | H8: The property charges no pet fee or pet rent today. New policy phased in on renewals over year one.
A9: Economic occupancy factor for per-unit charges | C9: 0.95 | D9: 0.95 | E9: 0.95 | F9: 0.95 | G9: 0.95 | H9: Consistent with CBRE's other-income forecast method.
A11: OTHER INCOME LINE ITEMS
A12: Water & Sewer Recovery (85% of expense) | B12: 97811.57 | C12: =0.85*Assumptions!$B$62 -> 76500 | D12: =C12*(1+Assumptions!$C$62) -> 79560 | E12: =D12*(1+Assumptions!$C$62) -> 82742.4 | F12: =E12*(1+Assumptions!$C$62) -> 86052.096 | G12: =F12*(1+Assumptions!$C$62) -> 89494.18 | H12: T-12 Utility Fees of $97,812 bundle water/sewer and valet trash. CBRE's forecast splits them and assumes 85% water/sewer recovery. Flexes with the water & sewer expense line.
A13: Valet Trash ($25/unit/month) | B13: 0 | C13: =25*12*Assumptions!$B$17*C$9*C$7 -> 25222.5 | D13: =C13/C$7*D$7*(1+Assumptions!D$51) -> 32906.955 | E13: =D13/D$7*E$7*(1+Assumptions!E$51) -> 35678.067 | F13: =E13/E$7*F$7*(1+Assumptions!F$51) -> 36748.409 | G13: =F13/F$7*G$7*(1+Assumptions!G$51) -> 37850.861 | H13: Broken out of Utility Fees per CBRE. A valet contract has been signed and the property starts paying for the service in Jan-2026, so the charge must be collected.
A14: Technology Fee ($49/unit/month) | B14: 13553 | C14: =49*12*Assumptions!$B$17*C$9*C$6 -> 56027.58 | D14: =C14/C$6*D$6*(1+Assumptions!D$51) -> 67892.244 | E14: =D14/D$6*E$6*(1+Assumptions!E$51) -> 69929.011 | F14: =E14/E$6*F$6*(1+Assumptions!F$51) -> 72026.882 | G14: =F14/F$6*G$6*(1+Assumptions!G$51) -> 74187.688 | H14: Offsets the $27.95/unit/month bulk internet expense. Contractual and already being billed.
A15: Carport Rent (74 carports @ $25/month) | B15: 16197 | C15: =B15 -> 16197 | D15: =C15*(1+Assumptions!D$51) -> 16682.91 | E15: =D15*(1+Assumptions!E$51) -> 17183.397 | F15: =E15*(1+Assumptions!F$51) -> 17698.899 | G15: =F15*(1+Assumptions!G$51) -> 18229.866 | H15: T-12 actual. 74 carports at $25; occupancy of the carports, not the units.
A16: Pet Rent ($30/month on 25% of units) | B16: 500 | C16: =30*12*Assumptions!$B$17*0.25*C$8 -> 5310 | D16: =C16/C$8*D$8*(1+Assumptions!D$51) -> 10938.6 | E16: =D16/D$8*E$8*(1+Assumptions!E$51) -> 11266.758 | F16: =E16/E$8*F$8*(1+Assumptions!F$51) -> 11604.761 | G16: =F16/F$8*G$8*(1+Assumptions!G$51) -> 11952.904 | H16: The property currently charges nothing for pets. A conservative $30/month on 25% of units; CBRE forecasts the same $10,620.
A17: Storage Rent (23 units available) | B17: 141 | C17: =3600 -> 3600 | D17: =C17*(1+Assumptions!D$51) -> 3708 | E17: =D17*(1+Assumptions!E$51) -> 3819.24 | F17: =E17*(1+Assumptions!F$51) -> 3933.8172 | G17: =F17*(1+Assumptions!G$51) -> 4051.8317 | H17: Only 5 of 23 storage units are rented today at $15-20. Underwritten at 12 rented at $25.
A18: Application & Administrative Fees | B18: 14846.11 | C18: =B18 -> 14846.11 | D18: =C18*(1+Assumptions!D$51) -> 15291.493 | E18: =D18*(1+Assumptions!E$51) -> 15750.238 | F18: =E18*(1+Assumptions!F$51) -> 16222.745 | G18: =F18*(1+Assumptions!G$51) -> 16709.428 | H18: T-12 actual: application, administrative, credit builder and transfer fees.
A19: Late & NSF Fees | B19: 10175 | C19: =B19 -> 10175 | D19: =C19*(1+Assumptions!D$51) -> 10480.25 | E19: =D19*(1+Assumptions!E$51) -> 10794.657 | F19: =E19*(1+Assumptions!F$51) -> 11118.497 | G19: =F19*(1+Assumptions!G$51) -> 11452.052 | H19: T-12 actual.
A20: Short-Term Lease Premiums | B20: 6440.71 | C20: =B20 -> 6440.71 | D20: =C20*(1+Assumptions!D$51) -> 6633.9313 | E20: =D20*(1+Assumptions!E$51) -> 6832.9492 | F20: =E20*(1+Assumptions!F$51) -> 7037.9377 | G20: =F20*(1+Assumptions!G$51) -> 7249.0758 | H20: T-12 actual. $75/month on 6-8 month renewals, $50/month on 9-11 month renewals.
A21: Lease Termination & Eviction Fees | B21: 7095.96 | C21: =4000 -> 4000 | D21: =C21*(1+Assumptions!D$51) -> 4120 | E21: =D21*(1+Assumptions!E$51) -> 4243.6 | F21: =E21*(1+Assumptions!F$51) -> 4370.908 | G21: =F21*(1+Assumptions!G$51) -> 4502.0352 | H21: T-12 $7,096. Haircut — volatile and partly a function of the current resident base.
A22: Damage Charges Recovered (net of SODA) | B22: 20467.4 | C22: =15000 -> 15000 | D22: =C22*(1+Assumptions!D$51) -> 15450 | E22: =D22*(1+Assumptions!E$51) -> 15913.5 | F22: =E22*(1+Assumptions!F$51) -> 16390.905 | G22: =F22*(1+Assumptions!G$51) -> 16882.632 | H22: T-12 $20,467. Haircut; should fall as the resident profile improves post-renovation.
A23: Miscellaneous & Utility Reimbursement | B23: 6160.78 | C23: =5000 -> 5000 | D23: =C23*(1+Assumptions!D$51) -> 5150 | E23: =D23*(1+Assumptions!E$51) -> 5304.5 | F23: =E23*(1+Assumptions!F$51) -> 5463.635 | G23: =F23*(1+Assumptions!G$51) -> 5627.5441 | H23: T-12 actual, lightly haircut.
A24: Washer/Dryer Rental | B24: 209 | C24: =0 -> 0 | D24: =C24*(1+Assumptions!D$51) -> 0 | E24: =D24*(1+Assumptions!E$51) -> 0 | F24: =E24*(1+Assumptions!F$51) -> 0 | G24: =F24*(1+Assumptions!G$51) -> 0 | H24: Programme discontinued, and in-unit laundry is now monetised through the rent premium. Set to zero to avoid double-counting.
A25: Total Other Income | B25: =SUM(B12:B24) -> 193597.53 | C25: =SUM(C12:C24) -> 238318.9 | D25: =SUM(D12:D24) -> 268814.38 | E25: =SUM(E12:E24) -> 279458.32 | F25: =SUM(F12:F24) -> 288669.49 | G25: =SUM(G12:G24) -> 298190.1
A26: Per Unit | B26: =B25/Assumptions!$B$17 -> 1640.657 | C26: =C25/Assumptions!$B$17 -> 2019.6517 | D26: =D25/Assumptions!$B$17 -> 2278.088 | E26: =E25/Assumptions!$B$17 -> 2368.2908 | F26: =F25/Assumptions!$B$17 -> 2446.3516 | G26: =G25/Assumptions!$B$17 -> 2527.0347
A27: % of Effective Gross Revenue | C27: =C25/'Annual Model'!C32 -> 0.12326809 | D27: =D25/'Annual Model'!D32 -> 0.12643178 | E27: =E25/'Annual Model'!E32 -> 0.1205756 | F27: =F25/'Annual Model'!F32 -> 0.11990429 | G27: =G25/'Annual Model'!G32 -> 0.1202096
A29: T-12 total operating other income of $193,598 ($1,641/unit) excludes $4,133 of interest income and treats bad debt as a revenue deduction. CBRE's Acquisition Forecast is $263,803 ($2,236/unit); the ancillary upside underwritten here — fully implementing the technology fee and valet trash charge, and introducing pet rent — is the same upside the OM identifies, phased in over the ramps shown above rather than assumed on day one.

Sheet Capex Budget
A1: CHATEAU IN THE WOODS | 4020 Monaco Drive, Indianapolis, IN 46220 | 118 Units
A2: Non-Unit Capital Budget — Deferred Maintenance, Building Systems & Amenities
A3: Blue = hardcoded input / lever · Black = formula · Green = link to another sheet · Yellow fill = key assumption
A5: Item | B5: Total Cost | C5: Per Unit | D5: Yr 1 % | E5: Yr 2 % | F5: Yr 3 % | G5: Yr 4 % | H5: Yr 5 % | I5: Scope and source
A6: Roof replacement — 3.5 of 5 roofs | B6: 360000 | C6: =B6/Assumptions!$B$17 -> 3050.8475 | D6: 0 | E6: 0.4 | F6: 0.4 | G6: 0.2 | H6: 0 | I6: OM: '3.5 of 5 roofs are older than 2006. They are rubber roofs. Assume they will need to be replaced within 10 years.' Building 4 cost $90,000 in 2020 and half of Building 5 cost $54,507 in 2024. A buyer in five years will price any roof we do not replace, so it is underwritten inside the hold.
A7: Asphalt patch, sealcoat & stripe | B7: 150000 | C7: =B7/Assumptions!$B$17 -> 1271.1864 | D7: 1 | E7: 0 | F7: 0 | G7: 0 | H7: 0 | I7: OM immediate need: parking lot and carport areas. The property spent $34,535 on concrete/asphalt in the T-12 alone and $38,749 in 2022 — patch-and-repair, not a programme.
A8: Sump pumps (4) & patio drain cleanout | B8: 40000 | C8: =B8/Assumptions!$B$17 -> 338.98305 | D8: 1 | E8: 0 | F8: 0 | G8: 0 | H8: 0 | I8: OM immediate need: 37 below-grade units, 4 sump pumps needed. Water intrusion risk in below-grade units is a live liability, not a cosmetic item.
A9: Window & sliding patio door glass | B9: 150000 | C9: =B9/Assumptions!$B$17 -> 1271.1864 | D9: 0.34 | E9: 0.33 | F9: 0.33 | G9: 0 | H9: 0 | I9: OM: original aluminium sliders and sliding patio doors, fogged glass replaced on turns. Executed with the interior renovation on each turn.
A10: Building entry system upgrades (20 entries) | B10: 60000 | C10: =B10/Assumptions!$B$17 -> 508.47458 | D10: 0.5 | E10: 0.5 | F10: 0 | G10: 0 | H10: 0 | I10: OM value-add item: upgrade building entry systems across the 20 building entries.
A11: Clubhouse, business centre & fitness refresh | B11: 75000 | C11: =B11/Assumptions!$B$17 -> 635.59322 | D11: 1 | E11: 0 | F11: 0 | G11: 0 | H11: 0 | I11: OM suggested amenity: update clubhouse furniture and decor. Required to support renovated rents.
A12: Dog park, grilling stations & pool deck seating | B12: 50000 | C12: =B12/Assumptions!$B$17 -> 423.72881 | D12: 1 | E12: 0 | F12: 0 | G12: 0 | H12: 0 | I12: OM suggested amenities. Low cost, high visibility on tours; supports the rent premium.
A13: Exterior paint, landscaping & signage refresh | B13: 100000 | C13: =B13/Assumptions!$B$17 -> 847.45763 | D13: 0.5 | E13: 0.5 | F13: 0 | G13: 0 | H13: 0 | I13: Curb appeal. Siding is fibre cement and was replaced in 2020 ($225,000), so this is paint and grounds, not envelope.
A14: Total Non-Unit Capital | B14: =SUM(B6:B13) -> 985000 | C14: =B14/Assumptions!$B$17 -> 8347.4576 | D14: =SUMPRODUCT($B$6:$B$13,D6:D13) -> 446000 | E14: =SUMPRODUCT($B$6:$B$13,E6:E13) -> 273500 | F14: =SUMPRODUCT($B$6:$B$13,F6:F13) -> 193500 | G14: =SUMPRODUCT($B$6:$B$13,G6:G13) -> 72000 | H14: =SUMPRODUCT($B$6:$B$13,H6:H13) -> 0
A15: Check: phasing sums to 100% | B15: =SUM(D14:H14)/B14 -> 1
A17: Excluded from this budget by choice, and therefore from the returns: converting the Building 4042 maintenance storage into two additional apartments, and converting the back 9 carports to garages plus a new maintenance shop. Both are identified in the OM and both are genuine, but at roughly $310,000 and $180,000 respectively they return only about 5-10% on cost against a 12.7% interior programme. They are upside we would pursue with a second look at scope and pricing, not underwritten value.

Sheet Reno Schedule
A1: CHATEAU IN THE WOODS | 4020 Monaco Drive, Indianapolis, IN 46220 | 118 Units
A2: 60-Month Renovation Schedule — Unit Delivery, Capital Spend and Downtime
A3: Blue = hardcoded input / lever · Black = formula · Green = link to another sheet · Yellow fill = key assumption
A5: Month | B5: Date | C5: Model Year | D5: Units Completed | E5: Cumulative Renovated | F5: Renovated Units Earning Premium | G5: Classic Units | H5: Reno'd w/ Existing W/D | I5: Reno'd Needing W/D Add | J5: Interior Capex | K5: W/D Install Capex | L5: Total Reno Capex | M5: Downtime Vac. (% of GPR)
A6: 1 | B6: =EDATE(Assumptions!$B$10,A6-1) -> 46235 | C6: =ROUNDUP(A6/12,0) -> 1 | D6: =IF(A6<Assumptions!$B$31,0,MAX(0,MIN(Assumptions!$B$32,Assumptions!$B$17-0))) -> 0 | E6: =0+D6 -> 0 | F6: =0 -> 0 | G6: =Assumptions!$B$17-F6 -> 118 | H6: =D6*Assumptions!$B$27/Assumptions!$B$17 -> 0 | I6: =D6*Assumptions!$B$28/Assumptions!$B$17 -> 0 | J6: =D6*Assumptions!$B$33 -> 0 | K6: =I6*Assumptions!$B$34 -> 0 | L6: =J6+K6 -> 0 | M6: =D6*Assumptions!$B$41/30/Assumptions!$B$17 -> 0
A7: 2 | B7: =EDATE(Assumptions!$B$10,A7-1) -> 46266 | C7: =ROUNDUP(A7/12,0) -> 1 | D7: =IF(A7<Assumptions!$B$31,0,MAX(0,MIN(Assumptions!$B$32,Assumptions!$B$17-E6))) -> 0 | E7: =E6+D7 -> 0 | F7: =E6 -> 0 | G7: =Assumptions!$B$17-F7 -> 118 | H7: =D7*Assumptions!$B$27/Assumptions!$B$17 -> 0 | I7: =D7*Assumptions!$B$28/Assumptions!$B$17 -> 0 | J7: =D7*Assumptions!$B$33 -> 0 | K7: =I7*Assumptions!$B$34 -> 0 | L7: =J7+K7 -> 0 | M7: =D7*Assumptions!$B$41/30/Assumptions!$B$17 -> 0
A8: 3 | B8: =EDATE(Assumptions!$B$10,A8-1) -> 46296 | C8: =ROUNDUP(A8/12,0) -> 1 | D8: =IF(A8<Assumptions!$B$31,0,MAX(0,MIN(Assumptions!$B$32,Assumptions!$B$17-E7))) -> 5 | E8: =E7+D8 -> 5 | F8: =E7 -> 0 | G8: =Assumptions!$B$17-F8 -> 118 | H8: =D8*Assumptions!$B$27/Assumptions!$B$17 -> 2.2457627 | I8: =D8*Assumptions!$B$28/Assumptions!$B$17 -> 2.7542373 | J8: =D8*Assumptions!$B$33 -> 65000 | K8: =I8*Assumptions!$B$34 -> 13771.186 | L8: =J8+K8 -> 78771.186 | M8: =D8*Assumptions!$B$41/30/Assumptions!$B$17 -> 0.019774011
A9: 4 | B9: =EDATE(Assumptions!$B$10,A9-1) -> 46327 | C9: =ROUNDUP(A9/12,0) -> 1 | D9: =IF(A9<Assumptions!$B$31,0,MAX(0,MIN(Assumptions!$B$32,Assumptions!$B$17-E8))) -> 5 | E9: =E8+D9 -> 10 | F9: =E8 -> 5 | G9: =Assumptions!$B$17-F9 -> 113 | H9: =D9*Assumptions!$B$27/Assumptions!$B$17 -> 2.2457627 | I9: =D9*Assumptions!$B$28/Assumptions!$B$17 -> 2.7542373 | J9: =D9*Assumptions!$B$33 -> 65000 | K9: =I9*Assumptions!$B$34 -> 13771.186 | L9: =J9+K9 -> 78771.186 | M9: =D9*Assumptions!$B$41/30/Assumptions!$B$17 -> 0.019774011
A10: 5 | B10: =EDATE(Assumptions!$B$10,A10-1) -> 46357 | C10: =ROUNDUP(A10/12,0) -> 1 | D10: =IF(A10<Assumptions!$B$31,0,MAX(0,MIN(Assumptions!$B$32,Assumptions!$B$17-E9))) -> 5 | E10: =E9+D10 -> 15 | F10: =E9 -> 10 | G10: =Assumptions!$B$17-F10 -> 108 | H10: =D10*Assumptions!$B$27/Assumptions!$B$17 -> 2.2457627 | I10: =D10*Assumptions!$B$28/Assumptions!$B$17 -> 2.7542373 | J10: =D10*Assumptions!$B$33 -> 65000 | K10: =I10*Assumptions!$B$34 -> 13771.186 | L10: =J10+K10 -> 78771.186 | M10: =D10*Assumptions!$B$41/30/Assumptions!$B$17 -> 0.019774011
A11: 6 | B11: =EDATE(Assumptions!$B$10,A11-1) -> 46388 | C11: =ROUNDUP(A11/12,0) -> 1 | D11: =IF(A11<Assumptions!$B$31,0,MAX(0,MIN(Assumptions!$B$32,Assumptions!$B$17-E10))) -> 5 | E11: =E10+D11 -> 20 | F11: =E10 -> 15 | G11: =Assumptions!$B$17-F11 -> 103 | H11: =D11*Assumptions!$B$27/Assumptions!$B$17 -> 2.2457627 | I11: =D11*Assumptions!$B$28/Assumptions!$B$17 -> 2.7542373 | J11: =D11*Assumptions!$B$33 -> 65000 | K11: =I11*Assumptions!$B$34 -> 13771.186 | L11: =J11+K11 -> 78771.186 | M11: =D11*Assumptions!$B$41/30/Assumptions!$B$17 -> 0.019774011
A12: 7 | B12: =EDATE(Assumptions!$B$10,A12-1) -> 46419 | C12: =ROUNDUP(A12/12,0) -> 1 | D12: =IF(A12<Assumptions!$B$31,0,MAX(0,MIN(Assumptions!$B$32,Assumptions!$B$17-E11))) -> 5 | E12: =E11+D12 -> 25 | F12: =E11 -> 20 | G12: =Assumptions!$B$17-F12 -> 98 | H12: =D12*Assumptions!$B$27/Assumptions!$B$17 -> 2.2457627 | I12: =D12*Assumptions!$B$28/Assumptions!$B$17 -> 2.7542373 | J12: =D12*Assumptions!$B$33 -> 65000 | K12: =I12*Assumptions!$B$34 -> 13771.186 | L12: =J12+K12 -> 78771.186 | M12: =D12*Assumptions!$B$41/30/Assumptions!$B$17 -> 0.019774011
A13: 8 | B13: =EDATE(Assumptions!$B$10,A13-1) -> 46447 | C13: =ROUNDUP(A13/12,0) -> 1 | D13: =IF(A13<Assumptions!$B$31,0,MAX(0,MIN(Assumptions!$B$32,Assumptions!$B$17-E12))) -> 5 | E13: =E12+D13 -> 30 | F13: =E12 -> 25 | G13: =Assumptions!$B$17-F13 -> 93 | H13: =D13*Assumptions!$B$27/Assumptions!$B$17 -> 2.2457627 | I13: =D13*Assumptions!$B$28/Assumptions!$B$17 -> 2.7542373 | J13: =D13*Assumptions!$B$33 -> 65000 | K13: =I13*Assumptions!$B$34 -> 13771.186 | L13: =J13+K13 -> 78771.186 | M13: =D13*Assumptions!$B$41/30/Assumptions!$B$17 -> 0.019774011
A14: 9 | B14: =EDATE(Assumptions!$B$10,A14-1) -> 46478 | C14: =ROUNDUP(A14/12,0) -> 1 | D14: =IF(A14<Assumptions!$B$31,0,MAX(0,MIN(Assumptions!$B$32,Assumptions!$B$17-E13))) -> 5 | E14: =E13+D14 -> 35 | F14: =E13 -> 30 | G14: =Assumptions!$B$17-F14 -> 88 | H14: =D14*Assumptions!$B$27/Assumptions!$B$17 -> 2.2457627 | I14: =D14*Assumptions!$B$28/Assumptions!$B$17 -> 2.7542373 | J14: =D14*Assumptions!$B$33 -> 65000 | K14: =I14*Assumptions!$B$34 -> 13771.186 | L14: =J14+K14 -> 78771.186 | M14: =D14*Assumptions!$B$41/30/Assumptions!$B$17 -> 0.019774011
A15: 10 | B15: =EDATE(Assumptions!$B$10,A15-1) -> 46508 | C15: =ROUNDUP(A15/12,0) -> 1 | D15: =IF(A15<Assumptions!$B$31,0,MAX(0,MIN(Assumptions!$B$32,Assumptions!$B$17-E14))) -> 5 | E15: =E14+D15 -> 40 | F15: =E14 -> 35 | G15: =Assumptions!$B$17-F15 -> 83 | H15: =D15*Assumptions!$B$27/Assumptions!$B$17 -> 2.2457627 | I15: =D15*Assumptions!$B$28/Assumptions!$B$17 -> 2.7542373 | J15: =D15*Assumptions!$B$33 -> 65000 | K15: =I15*Assumptions!$B$34 -> 13771.186 | L15: =J15+K15 -> 78771.186 | M15: =D15*Assumptions!$B$41/30/Assumptions!$B$17 -> 0.019774011
A16: 11 | B16: =EDATE(Assumptions!$B$10,A16-1) -> 46539 | C16: =ROUNDUP(A16/12,0) -> 1 | D16: =IF(A16<Assumptions!$B$31,0,MAX(0,MIN(Assumptions!$B$32,Assumptions!$B$17-E15))) -> 5 | E16: =E15+D16 -> 45 | F16: =E15 -> 40 | G16: =Assumptions!$B$17-F16 -> 78 | H16: =D16*Assumptions!$B$27/Assumptions!$B$17 -> 2.2457627 | I16: =D16*Assumptions!$B$28/Assumptions!$B$17 -> 2.7542373 | J16: =D16*Assumptions!$B$33 -> 65000 | K16: =I16*Assumptions!$B$34 -> 13771.186 | L16: =J16+K16 -> 78771.186 | M16: =D16*Assumptions!$B$41/30/Assumptions!$B$17 -> 0.019774011
A17: 12 | B17: =EDATE(Assumptions!$B$10,A17-1) -> 46569 | C17: =ROUNDUP(A17/12,0) -> 1 | D17: =IF(A17<Assumptions!$B$31,0,MAX(0,MIN(Assumptions!$B$32,Assumptions!$B$17-E16))) -> 5 | E17: =E16+D17 -> 50 | F17: =E16 -> 45 | G17: =Assumptions!$B$17-F17 -> 73 | H17: =D17*Assumptions!$B$27/Assumptions!$B$17 -> 2.2457627 | I17: =D17*Assumptions!$B$28/Assumptions!$B$17 -> 2.7542373 | J17: =D17*Assumptions!$B$33 -> 65000 | K17: =I17*Assumptions!$B$34 -> 13771.186 | L17: =J17+K17 -> 78771.186 | M17: =D17*Assumptions!$B$41/30/Assumptions!$B$17 -> 0.019774011
A18: 13 | B18: =EDATE(Assumptions!$B$10,A18-1) -> 46600 | C18: =ROUNDUP(A18/12,0) -> 2 | D18: =IF(A18<Assumptions!$B$31,0,MAX(0,MIN(Assumptions!$B$32,Assumptions!$B$17-E17))) -> 5 | E18: =E17+D18 -> 55 | F18: =E17 -> 50 | G18: =Assumptions!$B$17-F18 -> 68 | H18: =D18*Assumptions!$B$27/Assumptions!$B$17 -> 2.2457627 | I18: =D18*Assumptions!$B$28/Assumptions!$B$17 -> 2.7542373 | J18: =D18*Assumptions!$B$33 -> 65000 | K18: =I18*Assumptions!$B$34 -> 13771.186 | L18: =J18+K18 -> 78771.186 | M18: =D18*Assumptions!$B$41/30/Assumptions!$B$17 -> 0.019774011
... A65: 60 | B65: =EDATE(Assumptions!$B$10,A65-1) -> 48030 | C65: =ROUNDUP(A65/12,0) -> 5 | D65: =IF(A65<Assumptions!$B$31,0,MAX(0,MIN(Assumptions!$B$32,Assumptions!$B$17-E64))) -> 0 | E65: =E64+D65 -> 118 | F65: =E64 -> 118 | G65: =Assumptions!$B$17-F65 -> 0 | H65: =D65*Assumptions!$B$27/Assumptions!$B$17 -> 0 | I65: =D65*Assumptions!$B$28/Assumptions!$B$17 -> 0 | J65: =D65*Assumptions!$B$33 -> 0 | K65: =I65*Assumptions!$B$34 -> 0 | L65: =J65+K65 -> 0 | M65: =D65*Assumptions!$B$41/30/Assumptions!$B$17 -> 0
A66: Total | D66: =SUM(D6:D65) -> 118 | H66: =SUM(H6:H65) -> 53 | I66: =SUM(I6:I65) -> 65 | J66: =SUM(J6:J65) -> 1534000 | K66: =SUM(K6:K65) -> 325000 | L66: =SUM(L6:L65) -> 1859000
A68: ANNUAL SUMMARY — FEEDS THE CASH FLOW MODEL | C68: Year 1 | D68: Year 2 | E68: Year 3 | F68: Year 4 | G68: Year 5
A69: Units Completed in Year | C69: =SUMIFS($D$6:$D$65,$C$6:$C$65,1) -> 50 | D69: =SUMIFS($D$6:$D$65,$C$6:$C$65,2) -> 60 | E69: =SUMIFS($D$6:$D$65,$C$6:$C$65,3) -> 8 | F69: =SUMIFS($D$6:$D$65,$C$6:$C$65,4) -> 0 | G69: =SUMIFS($D$6:$D$65,$C$6:$C$65,5) -> 0
A70: Cumulative Renovated at Year End | C70: =SUMIFS($D$6:$D$65,$C$6:$C$65,"<="&1) -> 50 | D70: =SUMIFS($D$6:$D$65,$C$6:$C$65,"<="&2) -> 110 | E70: =SUMIFS($D$6:$D$65,$C$6:$C$65,"<="&3) -> 118 | F70: =SUMIFS($D$6:$D$65,$C$6:$C$65,"<="&4) -> 118 | G70: =SUMIFS($D$6:$D$65,$C$6:$C$65,"<="&5) -> 118
A71: Average Renovated Units Earning Premium | C71: =AVERAGEIFS($F$6:$F$65,$C$6:$C$65,1) -> 18.75 | D71: =AVERAGEIFS($F$6:$F$65,$C$6:$C$65,2) -> 77.5 | E71: =AVERAGEIFS($F$6:$F$65,$C$6:$C$65,3) -> 117.08333 | F71: =AVERAGEIFS($F$6:$F$65,$C$6:$C$65,4) -> 118 | G71: =AVERAGEIFS($F$6:$F$65,$C$6:$C$65,5) -> 118
A72: Average Classic Units | C72: =AVERAGEIFS($G$6:$G$65,$C$6:$C$65,1) -> 99.25 | D72: =AVERAGEIFS($G$6:$G$65,$C$6:$C$65,2) -> 40.5 | E72: =AVERAGEIFS($G$6:$G$65,$C$6:$C$65,3) -> 0.91666667 | F72: =AVERAGEIFS($G$6:$G$65,$C$6:$C$65,4) -> 0 | G72: =AVERAGEIFS($G$6:$G$65,$C$6:$C$65,5) -> 0
A73: Renovation Capital Spend | C73: =SUMIFS($L$6:$L$65,$C$6:$C$65,1) -> 787711.86 | D73: =SUMIFS($L$6:$L$65,$C$6:$C$65,2) -> 945254.24 | E73: =SUMIFS($L$6:$L$65,$C$6:$C$65,3) -> 126033.9 | F73: =SUMIFS($L$6:$L$65,$C$6:$C$65,4) -> 0 | G73: =SUMIFS($L$6:$L$65,$C$6:$C$65,5) -> 0
A74: Renovation Downtime Vacancy (% of GPR) | C74: =AVERAGEIFS($M$6:$M$65,$C$6:$C$65,1) -> 0.016478343 | D74: =AVERAGEIFS($M$6:$M$65,$C$6:$C$65,2) -> 0.019774011 | E74: =AVERAGEIFS($M$6:$M$65,$C$6:$C$65,3) -> 0.0026365348 | F74: =AVERAGEIFS($M$6:$M$65,$C$6:$C$65,4) -> 0 | G74: =AVERAGEIFS($M$6:$M$65,$C$6:$C$65,5) -> 0
A76: A unit renovated during month m begins earning the renovated rent in month m+1, so column F (renovated units earning the premium) is the prior month's cumulative count. Renovations are executed on natural turnover at 5 units a month, completing all 118 units in month 26.

Sheet Annual Model
